<?xml version="1.0"?>
<robot name="robomuse">


 <link name="base_footprint"/>

  <joint name="base_joint" type="fixed">
    <parent link="base_footprint"/>
    <child link="rm_chassis" />
    <origin xyz="0 0 0.010" rpy="0 0 0"/>
  </joint>

 <link name='rm_chassis'>

    <inertial>
      <mass value="10.0"/>
      <!--origin at CG-->
      <origin xyz="0 0 0.12" rpy=" 0 0 0"/>     
      <inertia ixx="1.195" ixy="0" ixz="0" iyy="1.3839" iyz="0"  izz="0.4883"/>
    </inertial>

   <visual name='chassis_visual'>
      <origin xyz="0 0 0" rpy=" 0 0 0"/>
      <geometry>
        
        <mesh filename="package://rm_description/models/rm_chassis.stl" scale = ".1 .1 .1"/>
      </geometry>
    </visual>
    <collision name='rmcollision'>
      <origin xyz="0 0 0" rpy=" 0 0 0"/>
      <geometry>       
        <mesh filename="package://rm_description/models/rm_chassis.stl" scale = ".1 .1 .1"/>
      </geometry>
    </collision>
   
 </link>
   
  <joint name="leftwheel_joint" type="continuous">
    <parent link="rm_chassis"/>
    <child link="rm_leftwheel" />
    <origin xyz="0 -.21 0.0620" rpy="0 0 0"/>
    <axis  xyz = "0 1 0"/>
    <!--<limit effort="0" velocity="0"/>
    <joint_properties damping="0.0" friction="0.0"/>-->
  </joint>

  <link name='rm_leftwheel'>

    <inertial>
      <mass value="0.1"/>
      <origin xyz="0 0 0" rpy=" 0 0 0"/>
      <inertia ixx="0.0001" ixy="0" ixz="0" iyy="0.0002" iyz="0"  izz="0.0001"/>
    </inertial>
    <visual name='leftwheel_visual'>
      <origin xyz="0 0 0" rpy=" 0 0 0"/>
      <geometry>
        <mesh filename="package://rm_description/models/rm_leftwheel.stl" scale = ".01 .01 .01"/>
      </geometry>
      <material name="black">
        <color rgba="0.0 0.0 0.0 1.0"/>
      </material>
    </visual>
    <collision name='leftwheel_collision'>
      <geometry>
        <mesh filename="package://rm_description/models/rm_leftwheel.stl" scale = ".01 .01 .01"/>
      </geometry>
    </collision>

    
  </link>

  <joint name="rightwheel_joint" type="continuous">
    <parent link="rm_chassis"/>
    <child link="rm_rightwheel" />
    <origin xyz="0 .21 0.0620" rpy="0 0 0"/>
    <axis  xyz = "0 1 0"/>
    <!--<limit effort="0" velocity="0"/>
    <joint_properties damping="0.0" friction="0.0"/>-->
  </joint>

  <link name='rm_rightwheel'>

    <inertial>
      <mass value="0.1"/>
      <origin xyz="0 0 0" rpy=" 0 0 0"/>
      <inertia ixx="0.0001" ixy="0" ixz="0" iyy="0.0002" iyz="0"  izz="0.0001"/>
    </inertial>
    <visual name='rightwheel_visual'>
      <origin xyz="0 0 0" rpy=" 0 0 0"/>
      <geometry>
        <mesh filename="package://rm_description/models/rm_leftwheel.stl" scale = ".01 .01 .01"/>
      </geometry>
    </visual>
    <collision name='rightwheel_collision'>
      <geometry>
        <mesh filename="package://rm_description/models/rm_leftwheel.stl" scale = ".01 .01 .01"/>
      </geometry>
    </collision>
  </link>


 <gazebo reference="rm_chassis">
 <mu1>0</mu1>
 <mu2>0</mu2>
 </gazebo>
<gazebo reference="rm_rightwheel">
 <mu1>50</mu1>
 <mu2>50</mu2>
 </gazebo>
 <gazebo reference="rm_leftwheel">
 <mu1>50</mu1>
 <mu2>50</mu2>
 </gazebo>


 <gazebo>

 <plugin name="differential_drive_controller" filename="libgazebo_ros_diff_drive.so">

 <alwaysOn>true</alwaysOn>
 <commandTopic>cmd_vel</commandTopic>
 <odometryTopic>odom</odometryTopic>
 <odometryFrame>odom</odometryFrame>
 <odometrySource>world</odometrySource>
 <publishOdomTF>true</publishOdomTF>
 <robotBaseFrame>base_footprint</robotBaseFrame>
 <publishWheelTF>false</publishWheelTF>
 <publishTf>true</publishTf>
 <publishWheelJointState>true</publishWheelJointState>
 <legacyMode>false</legacyMode>
 <updateRate>30</updateRate>
 <leftJoint>leftwheel_joint</leftJoint>
 <rightJoint>rightwheel_joint</rightJoint>
 <wheelSeparation>0.42</wheelSeparation>
 <wheelDiameter>0.125</wheelDiameter>
 <wheelAcceleration>0.2</wheelAcceleration>
 <wheelTorque>1</wheelTorque>
 <rosDebugLevel>na</rosDebugLevel>

 </plugin>

 </gazebo>







</robot>